Workbook

Sheet Read Me
A1: CSSP Task Control Hub — Quick Start
A2: Excel MVP for daily workload assignment, engineer updates, scope disposition, and target tracking.
A4: Purpose
A5: The workbook manages only CSSP tasks with status executing or processing. Source data is read-only; operational ownership, progress, targets, and scope decisions are recorded in separate append-only sheets.
A8: Daily Manager Workflow | E8: Engineer Workflow
A9: Step | B9: Action | C9: Control | E9: Step | F9: Action | G9: Control
A10: 1 | B10: Refresh / replace raw snapshots | C10: Load latest snapshots without editing Task Master formulas. | E10: 1 | F10: Find assigned work | G10: Filter by Current / Planned PIC.
A11: 2 | B11: Review processing queue | C11: Use Task Master and Engineer Capacity before assignment. | E11: 2 | F11: Append an update | G11: Add a new Engineer Updates row; never overwrite history.
A12: 3 | B12: Disposition to engineer | C12: Append Assignment History; Current Operational PIC updates automatically. | E12: 3 | F12: Record next action | G12: Include progress, next action, ETA, and blocker.
A13: 4 | B13: Publish daily targets | C13: Add executing tasks for the reporting date. | E13: 4 | F13: Flag scope issue | G13: Select Out-of-Scope Suspected and attach evidence.
A14: 5 | B14: Review scope exceptions | C14: Confirm or reject private-cloud/on-prem flags. | E14: 5 | F14: Record daily result | G14: Update Daily Targets result and completion evidence.
A15: 6 | B15: Close the day | C15: Review achieved, blocked, missed, and carried-over targets.
A18: Workbook Controls
A19: Blue cells | B19: User input.
A20: Gray cells | B20: Formula-driven; do not overwrite.
A21: Raw sheets | B21: Original daily snapshot values retained for traceability.
A22: Snapshot PIC | B22: Original gate_4_id from CSSP.
A23: Current Operational PIC | B23: Latest replacement, otherwise normalized Snapshot PIC.
A24: Confirmed OOS | B24: Excluded from workload but retained until CSSP reconciles.
A25: Daily target | B25: Historical date/request record; never delete misses or carryovers.
A28: Important Limitation
A29: Excel supports coauthoring, but it does not enforce strong row-level permissions. Store in SharePoint/OneDrive, protect source/formula sheets, retain version history, and restrict engineers to update input areas through team controls.

Sheet Dashboard
A1: Cloud Infrastructure Task Control Hub
A2: Operational view for executing and processing tasks. Reporting date is editable.
A4: Reporting Date | B4: 46252 | D4: Blue cells are manager/engineer inputs. Gray cells are formulas. Refresh raw snapshots only through the controlled import process.
A6: MANAGED BACKLOG | E6: EXECUTING | I6: PROCESSING / READY | M6: ASSIGNMENT EXCEPTIONS
A7: =COUNTIF('Task Master'!$A$5:$A$100,"<>") -> 96 | E7: =COUNTIF('Task Master'!$C$5:$C$100,"executing") -> 81 | I7: =COUNTIF('Task Master'!$C$5:$C$100,"processing") -> 15 | M7: =COUNTIF('Task Master'!$X$5:$X$100,"Executing without named engineer") -> 0
A12: TODAY'S TARGETS | E12: TARGETS ACHIEVED | I12: BLOCKED OR MISSED | M12: OOS PENDING REVIEW
A13: =COUNTIF('Daily Targets'!$A$5:$A$204,$B$4) -> 5 | E13: =COUNTIFS('Daily Targets'!$A$5:$A$204,$B$4,'Daily Targets'!$O$5:$O$204,"Yes") -> 0 | I13: =COUNTIFS('Daily Targets'!$A$5:$A$204,$B$4,'Daily Targets'!$K$5:$K$204,"Blocked")+COUNTIFS('Daily Targets'!$A$5:$A$204,$B$4,'Daily Targets'!$K$5:$K$204,"Missed") -> 0 | M13: =COUNTIF('Task Master'!$N$5:$N$100,"Pending Review") -> 0
A18: Engineer | B18: Projected Load | C18: Effective Capacity
A19: ='Engineer Capacity'!B5 -> Abdul Khoir | B19: ='Engineer Capacity'!K5 -> 26 | C19: ='Engineer Capacity'!F5 -> 12
A20: ='Engineer Capacity'!B6 -> Abhishek Bhowate | B20: ='Engineer Capacity'!K6 -> 8 | C20: ='Engineer Capacity'!F6 -> 12
A21: ='Engineer Capacity'!B7 -> Amarja Kawade | B21: ='Engineer Capacity'!K7 -> 42 | C21: ='Engineer Capacity'!F7 -> 12
A22: ='Engineer Capacity'!B8 -> Arun Karuppiah | B22: ='Engineer Capacity'!K8 -> 12 | C22: ='Engineer Capacity'!F8 -> 12
A23: ='Engineer Capacity'!B9 -> K Saktivelu | B23: ='Engineer Capacity'!K9 -> 6 | C23: ='Engineer Capacity'!F9 -> 12
A24: ='Engineer Capacity'!B10 -> Mardiansyah Rayasa | B24: ='Engineer Capacity'!K10 -> 17 | C24: ='Engineer Capacity'!F10 -> 12
A25: ='Engineer Capacity'!B11 -> Nilesh Sankpal | B25: ='Engineer Capacity'!K11 -> 0 | C25: ='Engineer Capacity'!F11 -> 12
A26: ='Engineer Capacity'!B12 -> Raditya Nugraha | B26: ='Engineer Capacity'!K12 -> 12 | C26: ='Engineer Capacity'!F12 -> 12
A27: ='Engineer Capacity'!B13 -> Sairam Villa | B27: ='Engineer Capacity'!K13 -> 0 | C27: ='Engineer Capacity'!F13 -> 12
A28: ='Engineer Capacity'!B14 -> Swaminadh Chirakala | B28: ='Engineer Capacity'!K14 -> 37 | C28: ='Engineer Capacity'!F14 -> 12
A29: ='Engineer Capacity'!B15 -> Venkatesh Kalikivayi | B29: ='Engineer Capacity'!K15 -> 8 | C29: ='Engineer Capacity'!F15 -> 12
A38: Backlog Status | B38: Count | C38: Share | E38: Today's Result | F38: Count | G38: Action
A39: executing | B39: =COUNTIF('Task Master'!$C$5:$C$100,A39) -> 81 | C39: =B39/SUM($B$39:$B$40) -> 0.84375 | E39: Achieved | F39: =COUNTIFS('Daily Targets'!$A$5:$A$204,$B$4,'Daily Targets'!$K$5:$K$204,"Achieved") -> 0 | G39: Review evidence
A40: processing | B40: =COUNTIF('Task Master'!$C$5:$C$100,A40) -> 15 | C40: =B40/SUM($B$39:$B$40) -> 0.15625 | E40: Blocked | F40: =COUNTIFS('Daily Targets'!$A$5:$A$204,$B$4,'Daily Targets'!$K$5:$K$204,"Blocked") -> 0 | G40: Escalate blocker
E41: Missed | F41: =COUNTIFS('Daily Targets'!$A$5:$A$204,$B$4,'Daily Targets'!$K$5:$K$204,"Missed") -> 0 | G41: Record carryover
E42: OOS Submitted | F42: =COUNTIFS('Daily Targets'!$A$5:$A$204,$B$4,'Daily Targets'!$K$5:$K$204,"Out-of-Scope Submitted") -> 0 | G42: Manager scope review

Sheet Task Master
A1: Task Master
A2: Read-only CSSP source fields plus formula-driven operational ownership, workload, progress, and exceptions.
A4: Request Number | B4: Task Type | C4: CSSP Status | D4: Snapshot Date | E4: Date Created | F4: Date Updated | G4: Application Name | H4: Project Name | I4: Request Size | J4: Snapshot PIC (gate_4_id) | K4: Current Operational PIC | L4: Assignment Mode | M4: Workload Points | N4: Manager Scope Decision | O4: Final Disposition | P4: Effective Workload | Q4: Latest Update | R4: Latest Engineer State | S4: Latest Workflow Stage | T4: Latest Progress | U4: Next Action | V4: Blocker | W4: ETA | X4: Exception | Y4: Source File
A5: CSSP10192809 | B5: Decommissioning | C5: processing | D5: 46251 | E5: 46196.13 | F5: 46237.316 | G5: Lab Information Management System - LIMS MLNG | H5: OCI MIGRATION - LIMS MLNG | I5: M | J5: CCoE Operations | K5: =IFERROR(LOOKUP(2,1/('Assignment History'!$B$5:$B$204=A5),'Assignment History'!$D$5:$D$204),IFERROR(VLOOKUP(J5,Configuration!$L$5:$M$50,2,FALSE),J5)) -> CCoE Operations | L5: =IF(K5=IFERROR(VLOOKUP(J5,Configuration!$L$5:$M$50,2,FALSE),J5),"Snapshot PIC","Replacement PIC") -> Snapshot PIC | M5: =IFERROR(VLOOKUP(I5,Configuration!$O$5:$P$8,2,FALSE),Configuration!$S$6) -> 2 | N5: =IFERROR(LOOKUP(2,1/('Scope Review'!$B$5:$B$204=A5),'Scope Review'!$G$5:$G$204),"Not Reviewed") -> Not Reviewed | O5: =IFERROR(LOOKUP(2,1/('Scope Review'!$B$5:$B$204=A5),'Scope Review'!$H$5:$H$204),"") | P5: =IF(AND(C5="executing",N5<>"Confirmed OOS"),M5,0) -> 0 | Q5: =IFERROR(LOOKUP(2,1/('Engineer Updates'!$B$5:$B$304=A5),'Engineer Updates'!$A$5:$A$304),"") | R5: =IFERROR(LOOKUP(2,1/('Engineer Updates'!$B$5:$B$304=A5),'Engineer Updates'!$E$5:$E$304),"") | S5: =IFERROR(LOOKUP(2,1/('Engineer Updates'!$B$5:$B$304=A5),'Engineer Updates'!$D$5:$D$304),"") | T5: =IFERROR(LOOKUP(2,1/('Engineer Updates'!$B$5:$B$304=A5),'Engineer Updates'!$F$5:$F$304),"") | U5: =IFERROR(LOOKUP(2,1/('Engineer Updates'!$B$5:$B$304=A5),'Engineer Updates'!$G$5:$G$304),"") | V5: =IFERROR(LOOKUP(2,1/('Engineer Updates'!$B$5:$B$304=A5),'Engineer Updates'!$H$5:$H$304),"") | W5: =IFERROR(LOOKUP(2,1/('Engineer Updates'!$B$5:$B$304=A5),'Engineer Updates'!$I$5:$I$304),"") | X5: =IF(AND(C5="executing",ISERROR(SEARCH("@",K5))),"Executing without named engineer",IF(AND(N5="Confirmed OOS",C5="executing"),"Confirmed OOS still executing","")) | Y5: CSSP-Decommisioning-1708.xlsx
A6: CSSP10237001 | B6: Decommissioning | C6: processing | D6: 46251 | E6: 46177.38 | F6: 46209.307 | G6: Energy Component as a Service - ECaaS | H6: PETRONAS Global Production System (PGPS) Energy Component as a Service (ECaaS) | I6: M | J6: CCoE Operations | K6: =IFERROR(LOOKUP(2,1/('Assignment History'!$B$5:$B$204=A6),'Assignment History'!$D$5:$D$204),IFERROR(VLOOKUP(J6,Configuration!$L$5:$M$50,2,FALSE),J6)) -> CCoE Operations | L6: =IF(K6=IFERROR(VLOOKUP(J6,Configuration!$L$5:$M$50,2,FALSE),J6),"Snapshot PIC","Replacement PIC") -> Snapshot PIC | M6: =IFERROR(VLOOKUP(I6,Configuration!$O$5:$P$8,2,FALSE),Configuration!$S$6) -> 2 | N6: =IFERROR(LOOKUP(2,1/('Scope Review'!$B$5:$B$204=A6),'Scope Review'!$G$5:$G$204),"Not Reviewed") -> Not Reviewed | O6: =IFERROR(LOOKUP(2,1/('Scope Review'!$B$5:$B$204=A6),'Scope Review'!$H$5:$H$204),"") | P6: =IF(AND(C6="executing",N6<>"Confirmed OOS"),M6,0) -> 0 | Q6: =IFERROR(LOOKUP(2,1/('Engineer Updates'!$B$5:$B$304=A6),'Engineer Updates'!$A$5:$A$304),"") | R6: =IFERROR(LOOKUP(2,1/('Engineer Updates'!$B$5:$B$304=A6),'Engineer Updates'!$E$5:$E$304),"") | S6: =IFERROR(LOOKUP(2,1/('Engineer Updates'!$B$5:$B$304=A6),'Engineer Updates'!$D$5:$D$304),"") | T6: =IFERROR(LOOKUP(2,1/('Engineer Updates'!$B$5:$B$304=A6),'Engineer Updates'!$F$5:$F$304),"") | U6: =IFERROR(LOOKUP(2,1/('Engineer Updates'!$B$5:$B$304=A6),'Engineer Updates'!$G$5:$G$304),"") | V6: =IFERROR(LOOKUP(2,1/('Engineer Updates'!$B$5:$B$304=A6),'Engineer Updates'!$H$5:$H$304),"") | W6: =IFERROR(LOOKUP(2,1/('Engineer Updates'!$B$5:$B$304=A6),'Engineer Updates'!$I$5:$I$304),"") | X6: =IF(AND(C6="executing",ISERROR(SEARCH("@",K6))),"Executing without named engineer",IF(AND(N6="Confirmed OOS",C6="executing"),"Confirmed OOS still executing","")) | Y6: CSSP-Decommisioning-1708.xlsx
A7: CSSP10340483 | B7: Decommissioning | C7: processing | D7: 46251 | E7: 46167.032 | F7: 46210.284 | G7: Instrument Reliability Digital Suite - IRIS | H7: [ALS] Implementation of Instrument Reliability Digital Suite (IRIS) for GTS | I7: S | J7: CCoE Operations | K7: =IFERROR(LOOKUP(2,1/('Assignment History'!$B$5:$B$204=A7),'Assignment History'!$D$5:$D$204),IFERROR(VLOOKUP(J7,Configuration!$L$5:$M$50,2,FALSE),J7)) -> CCoE Operations | L7: =IF(K7=IFERROR(VLOOKUP(J7,Configuration!$L$5:$M$50,2,FALSE),J7),"Snapshot PIC","Replacement PIC") -> Snapshot PIC | M7: =IFERROR(VLOOKUP(I7,Configuration!$O$5:$P$8,2,FALSE),Configuration!$S$6) -> 1 | N7: =IFERROR(LOOKUP(2,1/('Scope Review'!$B$5:$B$204=A7),'Scope Review'!$G$5:$G$204),"Not Reviewed") -> Not Reviewed | O7: =IFERROR(LOOKUP(2,1/('Scope Review'!$B$5:$B$204=A7),'Scope Review'!$H$5:$H$204),"") | P7: =IF(AND(C7="executing",N7<>"Confirmed OOS"),M7,0) -> 0 | Q7: =IFERROR(LOOKUP(2,1/('Engineer Updates'!$B$5:$B$304=A7),'Engineer Updates'!$A$5:$A$304),"") | R7: =IFERROR(LOOKUP(2,1/('Engineer Updates'!$B$5:$B$304=A7),'Engineer Updates'!$E$5:$E$304),"") | S7: =IFERROR(LOOKUP(2,1/('Engineer Updates'!$B$5:$B$304=A7),'Engineer Updates'!$D$5:$D$304),"") | T7: =IFERROR(LOOKUP(2,1/('Engineer Updates'!$B$5:$B$304=A7),'Engineer Updates'!$F$5:$F$304),"") | U7: =IFERROR(LOOKUP(2,1/('Engineer Updates'!$B$5:$B$304=A7),'Engineer Updates'!$G$5:$G$304),"") | V7: =IFERROR(LOOKUP(2,1/('Engineer Updates'!$B$5:$B$304=A7),'Engineer Updates'!$H$5:$H$304),"") | W7: =IFERROR(LOOKUP(2,1/('Engineer Updates'!$B$5:$B$304=A7),'Engineer Updates'!$I$5:$I$304),"") | X7: =IF(AND(C7="executing",ISERROR(SEARCH("@",K7))),"Executing without named engineer",IF(AND(N7="Confirmed OOS",C7="executing"),"Confirmed OOS still executing","")) | Y7: CSSP-Decommisioning-1708.xlsx
A8: CSSP10434338 | B8: Decommissioning | C8: processing | D8: 46251 | E8: 46196.125 | F8: 46209.312 | G8: Lab Information Management System - LIMS PPTSB | H8: OCI MIGRATION - Integrated Lab Information System (PPT) | I8: M | J8: CCoE Operations | K8: =IFERROR(LOOKUP(2,1/('Assignment History'!$B$5:$B$204=A8),'Assignment History'!$D$5:$D$204),IFERROR(VLOOKUP(J8,Configuration!$L$5:$M$50,2,FALSE),J8)) -> CCoE Operations | L8: =IF(K8=IFERROR(VLOOKUP(J8,Configuration!$L$5:$M$50,2,FALSE),J8),"Snapshot PIC","Replacement PIC") -> Snapshot PIC | M8: =IFERROR(VLOOKUP(I8,Configuration!$O$5:$P$8,2,FALSE),Configuration!$S$6) -> 2 | N8: =IFERROR(LOOKUP(2,1/('Scope Review'!$B$5:$B$204=A8),'Scope Review'!$G$5:$G$204),"Not Reviewed") -> Not Reviewed | O8: =IFERROR(LOOKUP(2,1/('Scope Review'!$B$5:$B$204=A8),'Scope Review'!$H$5:$H$204),"") | P8: =IF(AND(C8="executing",N8<>"Confirmed OOS"),M8,0) -> 0 | Q8: =IFERROR(LOOKUP(2,1/('Engineer Updates'!$B$5:$B$304=A8),'Engineer Updates'!$A$5:$A$304),"") | R8: =IFERROR(LOOKUP(2,1/('Engineer Updates'!$B$5:$B$304=A8),'Engineer Updates'!$E$5:$E$304),"") | S8: =IFERROR(LOOKUP(2,1/('Engineer Updates'!$B$5:$B$304=A8),'Engineer Updates'!$D$5:$D$304),"") | T8: =IFERROR(LOOKUP(2,1/('Engineer Updates'!$B$5:$B$304=A8),'Engineer Updates'!$F$5:$F$304),"") | U8: =IFERROR(LOOKUP(2,1/('Engineer Updates'!$B$5:$B$304=A8),'Engineer Updates'!$G$5:$G$304),"") | V8: =IFERROR(LOOKUP(2,1/('Engineer Updates'!$B$5:$B$304=A8),'Engineer Updates'!$H$5:$H$304),"") | W8: =IFERROR(LOOKUP(2,1/('Engineer Updates'!$B$5:$B$304=A8),'Engineer Updates'!$I$5:$I$304),"") | X8: =IF(AND(C8="executing",ISERROR(SEARCH("@",K8))),"Executing without named engineer",IF(AND(N8="Confirmed OOS",C8="executing"),"Confirmed OOS still executing","")) | Y8: CSSP-Decommisioning-1708.xlsx
A9: CSSP10958195 | B9: Decommissioning | C9: processing | D9: 46251 | E9: 46196.12 | F9: 46209.311 | G9: Lab Information Management System - LIMS MLNG | H9: OCI MIGRATION - Integrated Lab Information System (MLNG) | I9: M | J9: CCoE Operations | K9: =IFERROR(LOOKUP(2,1/('Assignment History'!$B$5:$B$204=A9),'Assignment History'!$D$5:$D$204),IFERROR(VLOOKUP(J9,Configuration!$L$5:$M$50,2,FALSE),J9)) -> CCoE Operations | L9: =IF(K9=IFERROR(VLOOKUP(J9,Configuration!$L$5:$M$50,2,FALSE),J9),"Snapshot PIC","Replacement PIC") -> Snapshot PIC | M9: =IFERROR(VLOOKUP(I9,Configuration!$O$5:$P$8,2,FALSE),Configuration!$S$6) -> 2 | N9: =IFERROR(LOOKUP(2,1/('Scope Review'!$B$5:$B$204=A9),'Scope Review'!$G$5:$G$204),"Not Reviewed") -> Not Reviewed | O9: =IFERROR(LOOKUP(2,1/('Scope Review'!$B$5:$B$204=A9),'Scope Review'!$H$5:$H$204),"") | P9: =IF(AND(C9="executing",N9<>"Confirmed OOS"),M9,0) -> 0 | Q9: =IFERROR(LOOKUP(2,1/('Engineer Updates'!$B$5:$B$304=A9),'Engineer Updates'!$A$5:$A$304),"") | R9: =IFERROR(LOOKUP(2,1/('Engineer Updates'!$B$5:$B$304=A9),'Engineer Updates'!$E$5:$E$304),"") | S9: =IFERROR(LOOKUP(2,1/('Engineer Updates'!$B$5:$B$304=A9),'Engineer Updates'!$D$5:$D$304),"") | T9: =IFERROR(LOOKUP(2,1/('Engineer Updates'!$B$5:$B$304=A9),'Engineer Updates'!$F$5:$F$304),"") | U9: =IFERROR(LOOKUP(2,1/('Engineer Updates'!$B$5:$B$304=A9),'Engineer Updates'!$G$5:$G$304),"") | V9: =IFERROR(LOOKUP(2,1/('Engineer Updates'!$B$5:$B$304=A9),'Engineer Updates'!$H$5:$H$304),"") | W9: =IFERROR(LOOKUP(2,1/('Engineer Updates'!$B$5:$B$304=A9),'Engineer Updates'!$I$5:$I$304),"") | X9: =IF(AND(C9="executing",ISERROR(SEARCH("@",K9))),"Executing without named engineer",IF(AND(N9="Confirmed OOS",C9="executing"),"Confirmed OOS still executing","")) | Y9: CSSP-Decommisioning-1708.xlsx
A10: CSSP10321088 | B10: Decommissioning | C10: processing | D10: 46251 | E10: 46245.32 | F10: 46251.168 | G10: RTMS | H10: Cloud Migration Program - PPTSB RTMS | I10: L | J10: IMS - CLOUD CSSP EXECUTOR | K10: =IFERROR(LOOKUP(2,1/('Assignment History'!$B$5:$B$204=A10),'Assignment History'!$D$5:$D$204),IFERROR(VLOOKUP(J10,Configuration!$L$5:$M$50,2,FALSE),J10)) -> IMS - CLOUD CSSP EXECUTOR | L10: =IF(K10=IFERROR(VLOOKUP(J10,Configuration!$L$5:$M$50,2,FALSE),J10),"Snapshot PIC","Replacement PIC") -> Snapshot PIC | M10: =IFERROR(VLOOKUP(I10,Configuration!$O$5:$P$8,2,FALSE),Configuration!$S$6) -> 3 | N10: =IFERROR(LOOKUP(2,1/('Scope Review'!$B$5:$B$204=A10),'Scope Review'!$G$5:$G$204),"Not Reviewed") -> Not Reviewed | O10: =IFERROR(LOOKUP(2,1/('Scope Review'!$B$5:$B$204=A10),'Scope Review'!$H$5:$H$204),"") | P10: =IF(AND(C10="executing",N10<>"Confirmed OOS"),M10,0) -> 0 | Q10: =IFERROR(LOOKUP(2,1/('Engineer Updates'!$B$5:$B$304=A10),'Engineer Updates'!$A$5:$A$304),"") | R10: =IFERROR(LOOKUP(2,1/('Engineer Updates'!$B$5:$B$304=A10),'Engineer Updates'!$E$5:$E$304),"") | S10: =IFERROR(LOOKUP(2,1/('Engineer Updates'!$B$5:$B$304=A10),'Engineer Updates'!$D$5:$D$304),"") | T10: =IFERROR(LOOKUP(2,1/('Engineer Updates'!$B$5:$B$304=A10),'Engineer Updates'!$F$5:$F$304),"") | U10: =IFERROR(LOOKUP(2,1/('Engineer Updates'!$B$5:$B$304=A10),'Engineer Updates'!$G$5:$G$304),"") | V10: =IFERROR(LOOKUP(2,1/('Engineer Updates'!$B$5:$B$304=A10),'Engineer Updates'!$H$5:$H$304),"") | W10: =IFERROR(LOOKUP(2,1/('Engineer Updates'!$B$5:$B$304=A10),'Engineer Updates'!$I$5:$I$304),"") | X10: =IF(AND(C10="executing",ISERROR(SEARCH("@",K10))),"Executing without named engineer",IF(AND(N10="Confirmed OOS",C10="executing"),"Confirmed OOS still executing","")) | Y10: CSSP-Decommisioning-1708.xlsx
A11: CSSP10484519 | B11: Decommissioning | C11: processing | D11: 46251 | E11: 46225.029 | F11: 46244.079 | G11: Danger Dodgers | H11: Pilot Deployment of Danger Dodgers at PCFK | I11: S | J11: IMS - CLOUD CSSP EXECUTOR | K11: =IFERROR(LOOKUP(2,1/('Assignment History'!$B$5:$B$204=A11),'Assignment History'!$D$5:$D$204),IFERROR(VLOOKUP(J11,Configuration!$L$5:$M$50,2,FALSE),J11)) -> IMS - CLOUD CSSP EXECUTOR | L11: =IF(K11=IFERROR(VLOOKUP(J11,Configuration!$L$5:$M$50,2,FALSE),J11),"Snapshot PIC","Replacement PIC") -> Snapshot PIC | M11: =IFERROR(VLOOKUP(I11,Configuration!$O$5:$P$8,2,FALSE),Configuration!$S$6) -> 1 | N11: =IFERROR(LOOKUP(2,1/('Scope Review'!$B$5:$B$204=A11),'Scope Review'!$G$5:$G$204),"Not Reviewed") -> Not Reviewed | O11: =IFERROR(LOOKUP(2,1/('Scope Review'!$B$5:$B$204=A11),'Scope Review'!$H$5:$H$204),"") | P11: =IF(AND(C11="executing",N11<>"Confirmed OOS"),M11,0) -> 0 | Q11: =IFERROR(LOOKUP(2,1/('Engineer Updates'!$B$5:$B$304=A11),'Engineer Updates'!$A$5:$A$304),"") | R11: =IFERROR(LOOKUP(2,1/('Engineer Updates'!$B$5:$B$304=A11),'Engineer Updates'!$E$5:$E$304),"") | S11: =IFERROR(LOOKUP(2,1/('Engineer Updates'!$B$5:$B$304=A11),'Engineer Updates'!$D$5:$D$304),"") | T11: =IFERROR(LOOKUP(2,1/('Engineer Updates'!$B$5:$B$304=A11),'Engineer Updates'!$F$5:$F$304),"") | U11: =IFERROR(LOOKUP(2,1/('Engineer Updates'!$B$5:$B$304=A11),'Engineer Updates'!$G$5:$G$304),"") | V11: =IFERROR(LOOKUP(2,1/('Engineer Updates'!$B$5:$B$304=A11),'Engineer Updates'!$H$5:$H$304),"") | W11: =IFERROR(LOOKUP(2,1/('Engineer Updates'!$B$5:$B$304=A11),'Engineer Updates'!$I$5:$I$304),"") | X11: =IF(AND(C11="executing",ISERROR(SEARCH("@",K11))),"Executing without named engineer",IF(AND(N11="Confirmed OOS",C11="executing"),"Confirmed OOS still executing","")) | Y11: CSSP-Decommisioning-1708.xlsx
A12: CSSP10588883 | B12: Decommissioning | C12: processing | D12: 46251 | E12: 46233.11 | F12: 46251.168 | G12: Falcon | H12: Implementation of Falcon - Engineering Visual Analytics Program (Work Package 1) - Requirements Gathering, High Level Design, and Data Gathering for GTS | I12: L | J12: IMS - CLOUD CSSP EXECUTOR | K12: =IFERROR(LOOKUP(2,1/('Assignment History'!$B$5:$B$204=A12),'Assignment History'!$D$5:$D$204),IFERROR(VLOOKUP(J12,Configuration!$L$5:$M$50,2,FALSE),J12)) -> IMS - CLOUD CSSP EXECUTOR | L12: =IF(K12=IFERROR(VLOOKUP(J12,Configuration!$L$5:$M$50,2,FALSE),J12),"Snapshot PIC","Replacement PIC") -> Snapshot PIC | M12: =IFERROR(VLOOKUP(I12,Configuration!$O$5:$P$8,2,FALSE),Configuration!$S$6) -> 3 | N12: =IFERROR(LOOKUP(2,1/('Scope Review'!$B$5:$B$204=A12),'Scope Review'!$G$5:$G$204),"Not Reviewed") -> Not Reviewed | O12: =IFERROR(LOOKUP(2,1/('Scope Review'!$B$5:$B$204=A12),'Scope Review'!$H$5:$H$204),"") | P12: =IF(AND(C12="executing",N12<>"Confirmed OOS"),M12,0) -> 0 | Q12: =IFERROR(LOOKUP(2,1/('Engineer Updates'!$B$5:$B$304=A12),'Engineer Updates'!$A$5:$A$304),"") | R12: =IFERROR(LOOKUP(2,1/('Engineer Updates'!$B$5:$B$304=A12),'Engineer Updates'!$E$5:$E$304),"") | S12: =IFERROR(LOOKUP(2,1/('Engineer Updates'!$B$5:$B$304=A12),'Engineer Updates'!$D$5:$D$304),"") | T12: =IFERROR(LOOKUP(2,1/('Engineer Updates'!$B$5:$B$304=A12),'Engineer Updates'!$F$5:$F$304),"") | U12: =IFERROR(LOOKUP(2,1/('Engineer Updates'!$B$5:$B$304=A12),'Engineer Updates'!$G$5:$G$304),"") | V12: =IFERROR(LOOKUP(2,1/('Engineer Updates'!$B$5:$B$304=A12),'Engineer Updates'!$H$5:$H$304),"") | W12: =IFERROR(LOOKUP(2,1/('Engineer Updates'!$B$5:$B$304=A12),'Engineer Updates'!$I$5:$I$304),"") | X12: =IF(AND(C12="executing",ISERROR(SEARCH("@",K12))),"Executing without named engineer",IF(AND(N12="Confirmed OOS",C12="executing"),"Confirmed OOS still executing","")) | Y12: CSSP-Decommisioning-1708.xlsx
A13: CSSP10589613 | B13: Decommissioning | C13: processing | D13: 46251 | E13: 46227.313 | F13: 46251.167 | G13: Rystad Energy Auth Server | H13: Hosting of Rystad Energy Ucube and Database for Upstream Strategy & Commercial | I13: L | J13: IMS - CLOUD CSSP EXECUTOR | K13: =IFERROR(LOOKUP(2,1/('Assignment History'!$B$5:$B$204=A13),'Assignment History'!$D$5:$D$204),IFERROR(VLOOKUP(J13,Configuration!$L$5:$M$50,2,FALSE),J13)) -> IMS - CLOUD CSSP EXECUTOR | L13: =IF(K13=IFERROR(VLOOKUP(J13,Configuration!$L$5:$M$50,2,FALSE),J13),"Snapshot PIC","Replacement PIC") -> Snapshot PIC | M13: =IFERROR(VLOOKUP(I13,Configuration!$O$5:$P$8,2,FALSE),Configuration!$S$6) -> 3 | N13: =IFERROR(LOOKUP(2,1/('Scope Review'!$B$5:$B$204=A13),'Scope Review'!$G$5:$G$204),"Not Reviewed") -> Not Reviewed | O13: =IFERROR(LOOKUP(2,1/('Scope Review'!$B$5:$B$204=A13),'Scope Review'!$H$5:$H$204),"") | P13: =IF(AND(C13="executing",N13<>"Confirmed OOS"),M13,0) -> 0 | Q13: =IFERROR(LOOKUP(2,1/('Engineer Updates'!$B$5:$B$304=A13),'Engineer Updates'!$A$5:$A$304),"") | R13: =IFERROR(LOOKUP(2,1/('Engineer Updates'!$B$5:$B$304=A13),'Engineer Updates'!$E$5:$E$304),"") | S13: =IFERROR(LOOKUP(2,1/('Engineer Updates'!$B$5:$B$304=A13),'Engineer Updates'!$D$5:$D$304),"") | T13: =IFERROR(LOOKUP(2,1/('Engineer Updates'!$B$5:$B$304=A13),'Engineer Updates'!$F$5:$F$304),"") | U13: =IFERROR(LOOKUP(2,1/('Engineer Updates'!$B$5:$B$304=A13),'Engineer Updates'!$G$5:$G$304),"") | V13: =IFERROR(LOOKUP(2,1/('Engineer Updates'!$B$5:$B$304=A13),'Engineer Updates'!$H$5:$H$304),"") | W13: =IFERROR(LOOKUP(2,1/('Engineer Updates'!$B$5:$B$304=A13),'Engineer Updates'!$I$5:$I$304),"") | X13: =IF(AND(C13="executing",ISERROR(SEARCH("@",K13))),"Executing without named engineer",IF(AND(N13="Confirmed OOS",C13="executing"),"Confirmed OOS still executing","")) | Y13: CSSP-Decommisioning-1708.xlsx
A14: CSSP10684299 | B14: Decommissioning | C14: processing | D14: 46251 | E14: 46164.348 | F14: 46239.267 | G14: Refinery of the Future - ROTF PRPC | H14: CTP - Refinery of the future (ROTF) - Feedstock | J14: IMS - CLOUD CSSP EXECUTOR | K14: =IFERROR(LOOKUP(2,1/('Assignment History'!$B$5:$B$204=A14),'Assignment History'!$D$5:$D$204),IFERROR(VLOOKUP(J14,Configuration!$L$5:$M$50,2,FALSE),J14)) -> IMS - CLOUD CSSP EXECUTOR | L14: =IF(K14=IFERROR(VLOOKUP(J14,Configuration!$L$5:$M$50,2,FALSE),J14),"Snapshot PIC","Replacement PIC") -> Snapshot PIC | M14: =IFERROR(VLOOKUP(I14,Configuration!$O$5:$P$8,2,FALSE),Configuration!$S$6) -> 2 | N14: =IFERROR(LOOKUP(2,1/('Scope Review'!$B$5:$B$204=A14),'Scope Review'!$G$5:$G$204),"Not Reviewed") -> Not Reviewed | O14: =IFERROR(LOOKUP(2,1/('Scope Review'!$B$5:$B$204=A14),'Scope Review'!$H$5:$H$204),"") | P14: =IF(AND(C14="executing",N14<>"Confirmed OOS"),M14,0) -> 0 | Q14: =IFERROR(LOOKUP(2,1/('Engineer Updates'!$B$5:$B$304=A14),'Engineer Updates'!$A$5:$A$304),"") | R14: =IFERROR(LOOKUP(2,1/('Engineer Updates'!$B$5:$B$304=A14),'Engineer Updates'!$E$5:$E$304),"") | S14: =IFERROR(LOOKUP(2,1/('Engineer Updates'!$B$5:$B$304=A14),'Engineer Updates'!$D$5:$D$304),"") | T14: =IFERROR(LOOKUP(2,1/('Engineer Updates'!$B$5:$B$304=A14),'Engineer Updates'!$F$5:$F$304),"") | U14: =IFERROR(LOOKUP(2,1/('Engineer Updates'!$B$5:$B$304=A14),'Engineer Updates'!$G$5:$G$304),"") | V14: =IFERROR(LOOKUP(2,1/('Engineer Updates'!$B$5:$B$304=A14),'Engineer Updates'!$H$5:$H$304),"") | W14: =IFERROR(LOOKUP(2,1/('Engineer Updates'!$B$5:$B$304=A14),'Engineer Updates'!$I$5:$I$304),"") | X14: =IF(AND(C14="executing",ISERROR(SEARCH("@",K14))),"Executing without named engineer",IF(AND(N14="Confirmed OOS",C14="executing"),"Confirmed OOS still executing","")) | Y14: CSSP-Decommisioning-1708.xlsx
A15: CSSP10715182 | B15: Decommissioning | C15: processing | D15: 46251 | E15: 46251.284 | F15: 46251.316 | G15: Claim Tracking System - CTS | H15: Cloud Migration Program - Claim Tracking System (CTS) | J15: IMS - CLOUD CSSP EXECUTOR | K15: =IFERROR(LOOKUP(2,1/('Assignment History'!$B$5:$B$204=A15),'Assignment History'!$D$5:$D$204),IFERROR(VLOOKUP(J15,Configuration!$L$5:$M$50,2,FALSE),J15)) -> IMS - CLOUD CSSP EXECUTOR | L15: =IF(K15=IFERROR(VLOOKUP(J15,Configuration!$L$5:$M$50,2,FALSE),J15),"Snapshot PIC","Replacement PIC") -> Snapshot PIC | M15: =IFERROR(VLOOKUP(I15,Configuration!$O$5:$P$8,2,FALSE),Configuration!$S$6) -> 2 | N15: =IFERROR(LOOKUP(2,1/('Scope Review'!$B$5:$B$204=A15),'Scope Review'!$G$5:$G$204),"Not Reviewed") -> Not Reviewed | O15: =IFERROR(LOOKUP(2,1/('Scope Review'!$B$5:$B$204=A15),'Scope Review'!$H$5:$H$204),"") | P15: =IF(AND(C15="executing",N15<>"Confirmed OOS"),M15,0) -> 0 | Q15: =IFERROR(LOOKUP(2,1/('Engineer Updates'!$B$5:$B$304=A15),'Engineer Updates'!$A$5:$A$304),"") | R15: =IFERROR(LOOKUP(2,1/('Engineer Updates'!$B$5:$B$304=A15),'Engineer Updates'!$E$5:$E$304),"") | S15: =IFERROR(LOOKUP(2,1/('Engineer Updates'!$B$5:$B$304=A15),'Engineer Updates'!$D$5:$D$304),"") | T15: =IFERROR(LOOKUP(2,1/('Engineer Updates'!$B$5:$B$304=A15),'Engineer Updates'!$F$5:$F$304),"") | U15: =IFERROR(LOOKUP(2,1/('Engineer Updates'!$B$5:$B$304=A15),'Engineer Updates'!$G$5:$G$304),"") | V15: =IFERROR(LOOKUP(2,1/('Engineer Updates'!$B$5:$B$304=A15),'Engineer Updates'!$H$5:$H$304),"") | W15: =IFERROR(LOOKUP(2,1/('Engineer Updates'!$B$5:$B$304=A15),'Engineer Updates'!$I$5:$I$304),"") | X15: =IF(AND(C15="executing",ISERROR(SEARCH("@",K15))),"Executing without named engineer",IF(AND(N15="Confirmed OOS",C15="executing"),"Confirmed OOS still executing","")) | Y15: CSSP-Decommisioning-1708.xlsx
A16: CSSP10936121 | B16: Decommissioning | C16: processing | D16: 46251 | E16: 46248.17 | F16: 46251.169 | G16: Plant Information - PI PCASB | H16: Implementation of PI Asset Framework (AF) and PI Vision for PCASB | I16: L | J16: IMS - CLOUD CSSP EXECUTOR | K16: =IFERROR(LOOKUP(2,1/('Assignment History'!$B$5:$B$204=A16),'Assignment History'!$D$5:$D$204),IFERROR(VLOOKUP(J16,Configuration!$L$5:$M$50,2,FALSE),J16)) -> IMS - CLOUD CSSP EXECUTOR | L16: =IF(K16=IFERROR(VLOOKUP(J16,Configuration!$L$5:$M$50,2,FALSE),J16),"Snapshot PIC","Replacement PIC") -> Snapshot PIC | M16: =IFERROR(VLOOKUP(I16,Configuration!$O$5:$P$8,2,FALSE),Configuration!$S$6) -> 3 | N16: =IFERROR(LOOKUP(2,1/('Scope Review'!$B$5:$B$204=A16),'Scope Review'!$G$5:$G$204),"Not Reviewed") -> Not Reviewed | O16: =IFERROR(LOOKUP(2,1/('Scope Review'!$B$5:$B$204=A16),'Scope Review'!$H$5:$H$204),"") | P16: =IF(AND(C16="executing",N16<>"Confirmed OOS"),M16,0) -> 0 | Q16: =IFERROR(LOOKUP(2,1/('Engineer Updates'!$B$5:$B$304=A16),'Engineer Updates'!$A$5:$A$304),"") | R16: =IFERROR(LOOKUP(2,1/('Engineer Updates'!$B$5:$B$304=A16),'Engineer Updates'!$E$5:$E$304),"") | S16: =IFERROR(LOOKUP(2,1/('Engineer Updates'!$B$5:$B$304=A16),'Engineer Updates'!$D$5:$D$304),"") | T16: =IFERROR(LOOKUP(2,1/('Engineer Updates'!$B$5:$B$304=A16),'Engineer Updates'!$F$5:$F$304),"") | U16: =IFERROR(LOOKUP(2,1/('Engineer Updates'!$B$5:$B$304=A16),'Engineer Updates'!$G$5:$G$304),"") | V16: =IFERROR(LOOKUP(2,1/('Engineer Updates'!$B$5:$B$304=A16),'Engineer Updates'!$H$5:$H$304),"") | W16: =IFERROR(LOOKUP(2,1/('Engineer Updates'!$B$5:$B$304=A16),'Engineer Updates'!$I$5:$I$304),"") | X16: =IF(AND(C16="executing",ISERROR(SEARCH("@",K16))),"Executing without named engineer",IF(AND(N16="Confirmed OOS",C16="executing"),"Confirmed OOS still executing","")) | Y16: CSSP-Decommisioning-1708.xlsx
A17: CSSP10506137 | B17: Provisioning | C17: processing | D17: 46251 | E17: 46247.254 | F17: 46247.257 | G17: Ansible Enterprise Configuration Management - AECM | H17: Ansible Enterprise Configuration Management | J17: IMS - CLOUD CSSP EXECUTOR | K17: =IFERROR(LOOKUP(2,1/('Assignment History'!$B$5:$B$204=A17),'Assignment History'!$D$5:$D$204),IFERROR(VLOOKUP(J17,Configuration!$L$5:$M$50,2,FALSE),J17)) -> IMS - CLOUD CSSP EXECUTOR | L17: =IF(K17=IFERROR(VLOOKUP(J17,Configuration!$L$5:$M$50,2,FALSE),J17),"Snapshot PIC","Replacement PIC") -> Snapshot PIC | M17: =IFERROR(VLOOKUP(I17,Configuration!$O$5:$P$8,2,FALSE),Configuration!$S$6) -> 2 | N17: =IFERROR(LOOKUP(2,1/('Scope Review'!$B$5:$B$204=A17),'Scope Review'!$G$5:$G$204),"Not Reviewed") -> Not Reviewed | O17: =IFERROR(LOOKUP(2,1/('Scope Review'!$B$5:$B$204=A17),'Scope Review'!$H$5:$H$204),"") | P17: =IF(AND(C17="executing",N17<>"Confirmed OOS"),M17,0) -> 0 | Q17: =IFERROR(LOOKUP(2,1/('Engineer Updates'!$B$5:$B$304=A17),'Engineer Updates'!$A$5:$A$304),"") | R17: =IFERROR(LOOKUP(2,1/('Engineer Updates'!$B$5:$B$304=A17),'Engineer Updates'!$E$5:$E$304),"") | S17: =IFERROR(LOOKUP(2,1/('Engineer Updates'!$B$5:$B$304=A17),'Engineer Updates'!$D$5:$D$304),"") | T17: =IFERROR(LOOKUP(2,1/('Engineer Updates'!$B$5:$B$304=A17),'Engineer Updates'!$F$5:$F$304),"") | U17: =IFERROR(LOOKUP(2,1/('Engineer Updates'!$B$5:$B$304=A17),'Engineer Updates'!$G$5:$G$304),"") | V17: =IFERROR(LOOKUP(2,1/('Engineer Updates'!$B$5:$B$304=A17),'Engineer Updates'!$H$5:$H$304),"") | W17: =IFERROR(LOOKUP(2,1/('Engineer Updates'!$B$5:$B$304=A17),'Engineer Updates'!$I$5:$I$304),"") | X17: =IF(AND(C17="executing",ISERROR(SEARCH("@",K17))),"Executing without named engineer",IF(AND(N17="Confirmed OOS",C17="executing"),"Confirmed OOS still executing","")) | Y17: CSSP-Provisioning-1708.xlsx
A18: CSSP10675946 | B18: Provisioning | C18: processing | D18: 46251 | E18: 46247.26 | F18: 46251.171 | G18: Zentory+ | H18: Zentory+ Integration Layer | I18: M | J18: IMS - CLOUD CSSP EXECUTOR | K18: =IFERROR(LOOKUP(2,1/('Assignment History'!$B$5:$B$204=A18),'Assignment History'!$D$5:$D$204),IFERROR(VLOOKUP(J18,Configuration!$L$5:$M$50,2,FALSE),J18)) -> IMS - CLOUD CSSP EXECUTOR | L18: =IF(K18=IFERROR(VLOOKUP(J18,Configuration!$L$5:$M$50,2,FALSE),J18),"Snapshot PIC","Replacement PIC") -> Snapshot PIC | M18: =IFERROR(VLOOKUP(I18,Configuration!$O$5:$P$8,2,FALSE),Configuration!$S$6) -> 2 | N18: =IFERROR(LOOKUP(2,1/('Scope Review'!$B$5:$B$204=A18),'Scope Review'!$G$5:$G$204),"Not Reviewed") -> Not Reviewed | O18: =IFERROR(LOOKUP(2,1/('Scope Review'!$B$5:$B$204=A18),'Scope Review'!$H$5:$H$204),"") | P18: =IF(AND(C18="executing",N18<>"Confirmed OOS"),M18,0) -> 0 | Q18: =IFERROR(LOOKUP(2,1/('Engineer Updates'!$B$5:$B$304=A18),'Engineer Updates'!$A$5:$A$304),"") | R18: =IFERROR(LOOKUP(2,1/('Engineer Updates'!$B$5:$B$304=A18),'Engineer Updates'!$E$5:$E$304),"") | S18: =IFERROR(LOOKUP(2,1/('Engineer Updates'!$B$5:$B$304=A18),'Engineer Updates'!$D$5:$D$304),"") | T18: =IFERROR(LOOKUP(2,1/('Engineer Updates'!$B$5:$B$304=A18),'Engineer Updates'!$F$5:$F$304),"") | U18: =IFERROR(LOOKUP(2,1/('Engineer Updates'!$B$5:$B$304=A18),'Engineer Updates'!$G$5:$G$304),"") | V18: =IFERROR(LOOKUP(2,1/('Engineer Updates'!$B$5:$B$304=A18),'Engineer Updates'!$H$5:$H$304),"") | W18: =IFERROR(LOOKUP(2,1/('Engineer Updates'!$B$5:$B$304=A18),'Engineer Updates'!$I$5:$I$304),"") | X18: =IF(AND(C18="executing",ISERROR(SEARCH("@",K18))),"Executing without named engineer",IF(AND(N18="Confirmed OOS",C18="executing"),"Confirmed OOS still executing","")) | Y18: CSSP-Provisioning-1708.xlsx
A19: CSSP10933294 | B19: Provisioning | C19: processing | D19: 46251 | E19: 46248.337 | F19: 46251.157 | G19: Cyber Security SENTINEL | H19: Onboarding of Centralised Log Collector and Security Information & Event Management (SIEM) for SETEL | I19: S | J19: IMS - CLOUD CSSP EXECUTOR | K19: =IFERROR(LOOKUP(2,1/('Assignment History'!$B$5:$B$204=A19),'Assignment History'!$D$5:$D$204),IFERROR(VLOOKUP(J19,Configuration!$L$5:$M$50,2,FALSE),J19)) -> IMS - CLOUD CSSP EXECUTOR | L19: =IF(K19=IFERROR(VLOOKUP(J19,Configuration!$L$5:$M$50,2,FALSE),J19),"Snapshot PIC","Replacement PIC") -> Snapshot PIC | M19: =IFERROR(VLOOKUP(I19,Configuration!$O$5:$P$8,2,FALSE),Configuration!$S$6) -> 1 | N19: =IFERROR(LOOKUP(2,1/('Scope Review'!$B$5:$B$204=A19),'Scope Review'!$G$5:$G$204),"Not Reviewed") -> Not Reviewed | O19: =IFERROR(LOOKUP(2,1/('Scope Review'!$B$5:$B$204=A19),'Scope Review'!$H$5:$H$204),"") | P19: =IF(AND(C19="executing",N19<>"Confirmed OOS"),M19,0) -> 0 | Q19: =IFERROR(LOOKUP(2,1/('Engineer Updates'!$B$5:$B$304=A19),'Engineer Updates'!$A$5:$A$304),"") | R19: =IFERROR(LOOKUP(2,1/('Engineer Updates'!$B$5:$B$304=A19),'Engineer Updates'!$E$5:$E$304),"") | S19: =IFERROR(LOOKUP(2,1/('Engineer Updates'!$B$5:$B$304=A19),'Engineer Updates'!$D$5:$D$304),"") | T19: =IFERROR(LOOKUP(2,1/('Engineer Updates'!$B$5:$B$304=A19),'Engineer Updates'!$F$5:$F$304),"") | U19: =IFERROR(LOOKUP(2,1/('Engineer Updates'!$B$5:$B$304=A19),'Engineer Updates'!$G$5:$G$304),"") | V19: =IFERROR(LOOKUP(2,1/('Engineer Updates'!$B$5:$B$304=A19),'Engineer Updates'!$H$5:$H$304),"") | W19: =IFERROR(LOOKUP(2,1/('Engineer Updates'!$B$5:$B$304=A19),'Engineer Updates'!$I$5:$I$304),"") | X19: =IF(AND(C19="executing",ISERROR(SEARCH("@",K19))),"Executing without named engineer",IF(AND(N19="Confirmed OOS",C19="executing"),"Confirmed OOS still executing","")) | Y19: CSSP-Provisioning-1708.xlsx
A20: CSSP10916071 | B20: Decommissioning | C20: executing | D20: 46251 | E20: 46196.124 | F20: 46251.32 | G20: Lab Information Management System - LIMS PPTSB | H20: OCI MIGRATION - LIMS PPTSB | I20: M | J20: abdul.khoir@petronas.com | K20: =IFERROR(LOOKUP(2,1/('Assignment History'!$B$5:$B$204=A20),'Assignment History'!$D$5:$D$204),IFERROR(VLOOKUP(J20,Configuration!$L$5:$M$50,2,FALSE),J20)) -> abdul.khoir@petronas.com | L20: =IF(K20=IFERROR(VLOOKUP(J20,Configuration!$L$5:$M$50,2,FALSE),J20),"Snapshot PIC","Replacement PIC") -> Snapshot PIC | M20: =IFERROR(VLOOKUP(I20,Configuration!$O$5:$P$8,2,FALSE),Configuration!$S$6) -> 2 | N20: =IFERROR(LOOKUP(2,1/('Scope Review'!$B$5:$B$204=A20),'Scope Review'!$G$5:$G$204),"Not Reviewed") -> Not Reviewed | O20: =IFERROR(LOOKUP(2,1/('Scope Review'!$B$5:$B$204=A20),'Scope Review'!$H$5:$H$204),"") | P20: =IF(AND(C20="executing",N20<>"Confirmed OOS"),M20,0) -> 2 | Q20: =IFERROR(LOOKUP(2,1/('Engineer Updates'!$B$5:$B$304=A20),'Engineer Updates'!$A$5:$A$304),"") -> 46251 | R20: =IFERROR(LOOKUP(2,1/('Engineer Updates'!$B$5:$B$304=A20),'Engineer Updates'!$E$5:$E$304),"") -> Not Started | S20: =IFERROR(LOOKUP(2,1/('Engineer Updates'!$B$5:$B$304=A20),'Engineer Updates'!$D$5:$D$304),"") -> 0 | T20: =IFERROR(LOOKUP(2,1/('Engineer Updates'!$B$5:$B$304=A20),'Engineer Updates'!$F$5:$F$304),"") -> 0 | U20: =IFERROR(LOOKUP(2,1/('Engineer Updates'!$B$5:$B$304=A20),'Engineer Updates'!$G$5:$G$304),"") -> 0 | V20: =IFERROR(LOOKUP(2,1/('Engineer Updates'!$B$5:$B$304=A20),'Engineer Updates'!$H$5:$H$304),"") -> 0 | W20: =IFERROR(LOOKUP(2,1/('Engineer Updates'!$B$5:$B$304=A20),'Engineer Updates'!$I$5:$I$304),"") -> 0 | X20: =IF(AND(C20="executing",ISERROR(SEARCH("@",K20))),"Executing without named engineer",IF(AND(N20="Confirmed OOS",C20="executing"),"Confirmed OOS still executing","")) | Y20: CSSP-Decommisioning-1708.xlsx
A21: CSSP10372916 | B21: Decommissioning | C21: executing | D21: 46251 | E21: 46226.128 | F21: 46233.106 | G21: Plant Information - PI MLNG | H21: Plant Information - PI MLNG created for PRIVATECLOUD project record | I21: M | J21: abhishek.bhowate@petronas.com | K21: =IFERROR(LOOKUP(2,1/('Assignment History'!$B$5:$B$204=A21),'Assignment History'!$D$5:$D$204),IFERROR(VLOOKUP(J21,Configuration!$L$5:$M$50,2,FALSE),J21)) -> abdul.khoir@petronas.com | L21: =IF(K21=IFERROR(VLOOKUP(J21,Configuration!$L$5:$M$50,2,FALSE),J21),"Snapshot PIC","Replacement PIC") -> Replacement PIC | M21: =IFERROR(VLOOKUP(I21,Configuration!$O$5:$P$8,2,FALSE),Configuration!$S$6) -> 2 | N21: =IFERROR(LOOKUP(2,1/('Scope Review'!$B$5:$B$204=A21),'Scope Review'!$G$5:$G$204),"Not Reviewed") -> Not Reviewed | O21: =IFERROR(LOOKUP(2,1/('Scope Review'!$B$5:$B$204=A21),'Scope Review'!$H$5:$H$204),"") | P21: =IF(AND(C21="executing",N21<>"Confirmed OOS"),M21,0) -> 2 | Q21: =IFERROR(LOOKUP(2,1/('Engineer Updates'!$B$5:$B$304=A21),'Engineer Updates'!$A$5:$A$304),"") -> 46251 | R21: =IFERROR(LOOKUP(2,1/('Engineer Updates'!$B$5:$B$304=A21),'Engineer Updates'!$E$5:$E$304),"") -> Not Started | S21: =IFERROR(LOOKUP(2,1/('Engineer Updates'!$B$5:$B$304=A21),'Engineer Updates'!$D$5:$D$304),"") -> 0 | T21: =IFERROR(LOOKUP(2,1/('Engineer Updates'!$B$5:$B$304=A21),'Engineer Updates'!$F$5:$F$304),"") -> 0 | U21: =IFERROR(LOOKUP(2,1/('Engineer Updates'!$B$5:$B$304=A21),'Engineer Updates'!$G$5:$G$304),"") -> 0 | V21: =IFERROR(LOOKUP(2,1/('Engineer Updates'!$B$5:$B$304=A21),'Engineer Updates'!$H$5:$H$304),"") -> 0 | W21: =IFERROR(LOOKUP(2,1/('Engineer Updates'!$B$5:$B$304=A21),'Engineer Updates'!$I$5:$I$304),"") -> 0 | X21: =IF(AND(C21="executing",ISERROR(SEARCH("@",K21))),"Executing without named engineer",IF(AND(N21="Confirmed OOS",C21="executing"),"Confirmed OOS still executing","")) | Y21: CSSP-Decommisioning-1708.xlsx
A22: CSSP10989463 | B22: Decommissioning | C22: executing | D22: 46251 | E22: 46209.158 | F22: 46209.169 | G22: Cloud Self Service Portal - CSSP | H22: Cloud Digitization - Cloud Self Service Portal | I22: S | J22: abhishek.bhowate@petronas.com | K22: =IFERROR(LOOKUP(2,1/('Assignment History'!$B$5:$B$204=A22),'Assignment History'!$D$5:$D$204),IFERROR(VLOOKUP(J22,Configuration!$L$5:$M$50,2,FALSE),J22)) -> arun.karuppiah@petronas.com | L22: =IF(K22=IFERROR(VLOOKUP(J22,Configuration!$L$5:$M$50,2,FALSE),J22),"Snapshot PIC","Replacement PIC") -> Replacement PIC | M22: =IFERROR(VLOOKUP(I22,Configuration!$O$5:$P$8,2,FALSE),Configuration!$S$6) -> 1 | N22: =IFERROR(LOOKUP(2,1/('Scope Review'!$B$5:$B$204=A22),'Scope Review'!$G$5:$G$204),"Not Reviewed") -> Not Reviewed | O22: =IFERROR(LOOKUP(2,1/('Scope Review'!$B$5:$B$204=A22),'Scope Review'!$H$5:$H$204),"") | P22: =IF(AND(C22="executing",N22<>"Confirmed OOS"),M22,0) -> 1 | Q22: =IFERROR(LOOKUP(2,1/('Engineer Updates'!$B$5:$B$304=A22),'Engineer Updates'!$A$5:$A$304),"") -> 46251 | R22: =IFERROR(LOOKUP(2,1/('Engineer Updates'!$B$5:$B$304=A22),'Engineer Updates'!$E$5:$E$304),"") -> Not Started | S22: =IFERROR(LOOKUP(2,1/('Engineer Updates'!$B$5:$B$304=A22),'Engineer Updates'!$D$5:$D$304),"") -> 0 | T22: =IFERROR(LOOKUP(2,1/('Engineer Updates'!$B$5:$B$304=A22),'Engineer Updates'!$F$5:$F$304),"") -> 0 | U22: =IFERROR(LOOKUP(2,1/('Engineer Updates'!$B$5:$B$304=A22),'Engineer Updates'!$G$5:$G$304),"") -> 0 | V22: =IFERROR(LOOKUP(2,1/('Engineer Updates'!$B$5:$B$304=A22),'Engineer Updates'!$H$5:$H$304),"") -> 0 | W22: =IFERROR(LOOKUP(2,1/('Engineer Updates'!$B$5:$B$304=A22),'Engineer Updates'!$I$5:$I$304),"") -> 0 | X22: =IF(AND(C22="executing",ISERROR(SEARCH("@",K22))),"Executing without named engineer",IF(AND(N22="Confirmed OOS",C22="executing"),"Confirmed OOS still executing","")) | Y22: CSSP-Decommisioning-1708.xlsx
A23: CSSP10186192 | B23: Decommissioning | C23: executing | D23: 46251 | E23: 46233.11 | F23: 46246.652 | G23: Falcon | H23: FALCON for CORIMS Image Analytics (IA) for Composite Repair Module for GTS | I23: M | J23: amarja.kawade@petronas.com | K23: =IFERROR(LOOKUP(2,1/('Assignment History'!$B$5:$B$204=A23),'Assignment History'!$D$5:$D$204),IFERROR(VLOOKUP(J23,Configuration!$L$5:$M$50,2,FALSE),J23)) -> amarja.kawade@petronas.com | L23: =IF(K23=IFERROR(VLOOKUP(J23,Configuration!$L$5:$M$50,2,FALSE),J23),"Snapshot PIC","Replacement PIC") -> Snapshot PIC | M23: =IFERROR(VLOOKUP(I23,Configuration!$O$5:$P$8,2,FALSE),Configuration!$S$6) -> 2 | N23: =IFERROR(LOOKUP(2,1/('Scope Review'!$B$5:$B$204=A23),'Scope Review'!$G$5:$G$204),"Not Reviewed") -> Not Reviewed | O23: =IFERROR(LOOKUP(2,1/('Scope Review'!$B$5:$B$204=A23),'Scope Review'!$H$5:$H$204),"") | P23: =IF(AND(C23="executing",N23<>"Confirmed OOS"),M23,0) -> 2 | Q23: =IFERROR(LOOKUP(2,1/('Engineer Updates'!$B$5:$B$304=A23),'Engineer Updates'!$A$5:$A$304),"") -> 46251 | R23: =IFERROR(LOOKUP(2,1/('Engineer Updates'!$B$5:$B$304=A23),'Engineer Updates'!$E$5:$E$304),"") -> Not Started | S23: =IFERROR(LOOKUP(2,1/('Engineer Updates'!$B$5:$B$304=A23),'Engineer Updates'!$D$5:$D$304),"") -> 0 | T23: =IFERROR(LOOKUP(2,1/('Engineer Updates'!$B$5:$B$304=A23),'Engineer Updates'!$F$5:$F$304),"") -> 0 | U23: =IFERROR(LOOKUP(2,1/('Engineer Updates'!$B$5:$B$304=A23),'Engineer Updates'!$G$5:$G$304),"") -> 0 | V23: =IFERROR(LOOKUP(2,1/('Engineer Updates'!$B$5:$B$304=A23),'Engineer Updates'!$H$5:$H$304),"") -> 0 | W23: =IFERROR(LOOKUP(2,1/('Engineer Updates'!$B$5:$B$304=A23),'Engineer Updates'!$I$5:$I$304),"") -> 0 | X23: =IF(AND(C23="executing",ISERROR(SEARCH("@",K23))),"Executing without named engineer",IF(AND(N23="Confirmed OOS",C23="executing"),"Confirmed OOS still executing","")) | Y23: CSSP-Decommisioning-1708.xlsx
A24: CSSP10187579 | B24: Decommissioning | C24: executing | D24: 46251 | E24: 46226.089 | F24: 46231.205 | G24: IMIM / PCSB - Sabah Asset Project | H24: IMIM / PCSB - Sabah Asset Project created for PRIVATECLOUD project record | I24: S | J24: amarja.kawade@petronas.com | K24: =IFERROR(LOOKUP(2,1/('Assignment History'!$B$5:$B$204=A24),'Assignment History'!$D$5:$D$204),IFERROR(VLOOKUP(J24,Configuration!$L$5:$M$50,2,FALSE),J24)) -> amarja.kawade@petronas.com | L24: =IF(K24=IFERROR(VLOOKUP(J24,Configuration!$L$5:$M$50,2,FALSE),J24),"Snapshot PIC","Replacement PIC") -> Snapshot PIC | M24: =IFERROR(VLOOKUP(I24,Configuration!$O$5:$P$8,2,FALSE),Configuration!$S$6) -> 1 | N24: =IFERROR(LOOKUP(2,1/('Scope Review'!$B$5:$B$204=A24),'Scope Review'!$G$5:$G$204),"Not Reviewed") -> Not Reviewed | O24: =IFERROR(LOOKUP(2,1/('Scope Review'!$B$5:$B$204=A24),'Scope Review'!$H$5:$H$204),"") | P24: =IF(AND(C24="executing",N24<>"Confirmed OOS"),M24,0) -> 1 | Q24: =IFERROR(LOOKUP(2,1/('Engineer Updates'!$B$5:$B$304=A24),'Engineer Updates'!$A$5:$A$304),"") -> 46251 | R24: =IFERROR(LOOKUP(2,1/('Engineer Updates'!$B$5:$B$304=A24),'Engineer Updates'!$E$5:$E$304),"") -> Not Started | S24: =IFERROR(LOOKUP(2,1/('Engineer Updates'!$B$5:$B$304=A24),'Engineer Updates'!$D$5:$D$304),"") -> 0 | T24: =IFERROR(LOOKUP(2,1/('Engineer Updates'!$B$5:$B$304=A24),'Engineer Updates'!$F$5:$F$304),"") -> 0 | U24: =IFERROR(LOOKUP(2,1/('Engineer Updates'!$B$5:$B$304=A24),'Engineer Updates'!$G$5:$G$304),"") -> 0 | V24: =IFERROR(LOOKUP(2,1/('Engineer Updates'!$B$5:$B$304=A24),'Engineer Updates'!$H$5:$H$304),"") -> 0 | W24: =IFERROR(LOOKUP(2,1/('Engineer Updates'!$B$5:$B$304=A24),'Engineer Updates'!$I$5:$I$304),"") -> 0 | X24: =IF(AND(C24="executing",ISERROR(SEARCH("@",K24))),"Executing without named engineer",IF(AND(N24="Confirmed OOS",C24="executing"),"Confirmed OOS still executing","")) | Y24: CSSP-Decommisioning-1708.xlsx
A25: CSSP10323752 | B25: Decommissioning | C25: executing | D25: 46251 | E25: 46199.354 | F25: 46247.116 | G25: M365 Exchange 2016 for Centralised Automation Management Console | H25: M365-Microsoft Exchange Edge server for Address Rewriting | I25: S | J25: amarja.kawade@petronas.com | K25: =IFERROR(LOOKUP(2,1/('Assignment History'!$B$5:$B$204=A25),'Assignment History'!$D$5:$D$204),IFERROR(VLOOKUP(J25,Configuration!$L$5:$M$50,2,FALSE),J25)) -> amarja.kawade@petronas.com | L25: =IF(K25=IFERROR(VLOOKUP(J25,Configuration!$L$5:$M$50,2,FALSE),J25),"Snapshot PIC","Replacement PIC") -> Snapshot PIC | M25: =IFERROR(VLOOKUP(I25,Configuration!$O$5:$P$8,2,FALSE),Configuration!$S$6) -> 1 | N25: =IFERROR(LOOKUP(2,1/('Scope Review'!$B$5:$B$204=A25),'Scope Review'!$G$5:$G$204),"Not Reviewed") -> Not Reviewed | O25: =IFERROR(LOOKUP(2,1/('Scope Review'!$B$5:$B$204=A25),'Scope Review'!$H$5:$H$204),"") | P25: =IF(AND(C25="executing",N25<>"Confirmed OOS"),M25,0) -> 1 | Q25: =IFERROR(LOOKUP(2,1/('Engineer Updates'!$B$5:$B$304=A25),'Engineer Updates'!$A$5:$A$304),"") -> 46251 | R25: =IFERROR(LOOKUP(2,1/('Engineer Updates'!$B$5:$B$304=A25),'Engineer Updates'!$E$5:$E$304),"") -> Not Started | S25: =IFERROR(LOOKUP(2,1/('Engineer Updates'!$B$5:$B$304=A25),'Engineer Updates'!$D$5:$D$304),"") -> 0 | T25: =IFERROR(LOOKUP(2,1/('Engineer Updates'!$B$5:$B$304=A25),'Engineer Updates'!$F$5:$F$304),"") -> 0 | U25: =IFERROR(LOOKUP(2,1/('Engineer Updates'!$B$5:$B$304=A25),'Engineer Updates'!$G$5:$G$304),"") -> 0 | V25: =IFERROR(LOOKUP(2,1/('Engineer Updates'!$B$5:$B$304=A25),'Engineer Updates'!$H$5:$H$304),"") -> 0 | W25: =IFERROR(LOOKUP(2,1/('Engineer Updates'!$B$5:$B$304=A25),'Engineer Updates'!$I$5:$I$304),"") -> 0 | X25: =IF(AND(C25="executing",ISERROR(SEARCH("@",K25))),"Executing without named engineer",IF(AND(N25="Confirmed OOS",C25="executing"),"Confirmed OOS still executing","")) | Y25: CSSP-Decommisioning-1708.xlsx
A26: CSSP10327858 | B26: Decommissioning | C26: executing | D26: 46251 | E26: 46226.263 | F26: 46233.105 | G26: Data Logger ODM with OSISoft PI System | H26: Data Logger ODM with OSISoft PI System created for PRIVATECLOUD project record | I26: M | J26: amarja.kawade@petronas.com | K26: =IFERROR(LOOKUP(2,1/('Assignment History'!$B$5:$B$204=A26),'Assignment History'!$D$5:$D$204),IFERROR(VLOOKUP(J26,Configuration!$L$5:$M$50,2,FALSE),J26)) -> amarja.kawade@petronas.com | L26: =IF(K26=IFERROR(VLOOKUP(J26,Configuration!$L$5:$M$50,2,FALSE),J26),"Snapshot PIC","Replacement PIC") -> Snapshot PIC | M26: =IFERROR(VLOOKUP(I26,Configuration!$O$5:$P$8,2,FALSE),Configuration!$S$6) -> 2 | N26: =IFERROR(LOOKUP(2,1/('Scope Review'!$B$5:$B$204=A26),'Scope Review'!$G$5:$G$204),"Not Reviewed") -> Not Reviewed | O26: =IFERROR(LOOKUP(2,1/('Scope Review'!$B$5:$B$204=A26),'Scope Review'!$H$5:$H$204),"") | P26: =IF(AND(C26="executing",N26<>"Confirmed OOS"),M26,0) -> 2 | Q26: =IFERROR(LOOKUP(2,1/('Engineer Updates'!$B$5:$B$304=A26),'Engineer Updates'!$A$5:$A$304),"") -> 46251 | R26: =IFERROR(LOOKUP(2,1/('Engineer Updates'!$B$5:$B$304=A26),'Engineer Updates'!$E$5:$E$304),"") -> Not Started | S26: =IFERROR(LOOKUP(2,1/('Engineer Updates'!$B$5:$B$304=A26),'Engineer Updates'!$D$5:$D$304),"") -> 0 | T26: =IFERROR(LOOKUP(2,1/('Engineer Updates'!$B$5:$B$304=A26),'Engineer Updates'!$F$5:$F$304),"") -> 0 | U26: =IFERROR(LOOKUP(2,1/('Engineer Updates'!$B$5:$B$304=A26),'Engineer Updates'!$G$5:$G$304),"") -> 0 | V26: =IFERROR(LOOKUP(2,1/('Engineer Updates'!$B$5:$B$304=A26),'Engineer Updates'!$H$5:$H$304),"") -> 0 | W26: =IFERROR(LOOKUP(2,1/('Engineer Updates'!$B$5:$B$304=A26),'Engineer Updates'!$I$5:$I$304),"") -> 0 | X26: =IF(AND(C26="executing",ISERROR(SEARCH("@",K26))),"Executing without named engineer",IF(AND(N26="Confirmed OOS",C26="executing"),"Confirmed OOS still executing","")) | Y26: CSSP-Decommisioning-1708.xlsx
A27: CSSP10376841 | B27: Decommissioning | C27: executing | D27: 46251 | E27: 46237.103 | F27: 46246.651 | G27: Capability Integrated Management System - CIMS | H27: Upstream Shared Support Services (SecOps) FY2025 for MA, IVA, AD & SA | I27: M | J27: amarja.kawade@petronas.com | K27: =IFERROR(LOOKUP(2,1/('Assignment History'!$B$5:$B$204=A27),'Assignment History'!$D$5:$D$204),IFERROR(VLOOKUP(J27,Configuration!$L$5:$M$50,2,FALSE),J27)) -> amarja.kawade@petronas.com | L27: =IF(K27=IFERROR(VLOOKUP(J27,Configuration!$L$5:$M$50,2,FALSE),J27),"Snapshot PIC","Replacement PIC") -> Snapshot PIC | M27: =IFERROR(VLOOKUP(I27,Configuration!$O$5:$P$8,2,FALSE),Configuration!$S$6) -> 2 | N27: =IFERROR(LOOKUP(2,1/('Scope Review'!$B$5:$B$204=A27),'Scope Review'!$G$5:$G$204),"Not Reviewed") -> Not Reviewed | O27: =IFERROR(LOOKUP(2,1/('Scope Review'!$B$5:$B$204=A27),'Scope Review'!$H$5:$H$204),"") | P27: =IF(AND(C27="executing",N27<>"Confirmed OOS"),M27,0) -> 2 | Q27: =IFERROR(LOOKUP(2,1/('Engineer Updates'!$B$5:$B$304=A27),'Engineer Updates'!$A$5:$A$304),"") -> 46251 | R27: =IFERROR(LOOKUP(2,1/('Engineer Updates'!$B$5:$B$304=A27),'Engineer Updates'!$E$5:$E$304),"") -> Not Started | S27: =IFERROR(LOOKUP(2,1/('Engineer Updates'!$B$5:$B$304=A27),'Engineer Updates'!$D$5:$D$304),"") -> 0 | T27: =IFERROR(LOOKUP(2,1/('Engineer Updates'!$B$5:$B$304=A27),'Engineer Updates'!$F$5:$F$304),"") -> 0 | U27: =IFERROR(LOOKUP(2,1/('Engineer Updates'!$B$5:$B$304=A27),'Engineer Updates'!$G$5:$G$304),"") -> 0 | V27: =IFERROR(LOOKUP(2,1/('Engineer Updates'!$B$5:$B$304=A27),'Engineer Updates'!$H$5:$H$304),"") -> 0 | W27: =IFERROR(LOOKUP(2,1/('Engineer Updates'!$B$5:$B$304=A27),'Engineer Updates'!$I$5:$I$304),"") -> 0 | X27: =IF(AND(C27="executing",ISERROR(SEARCH("@",K27))),"Executing without named engineer",IF(AND(N27="Confirmed OOS",C27="executing"),"Confirmed OOS still executing","")) | Y27: CSSP-Decommisioning-1708.xlsx
A28: CSSP10413108 | B28: Decommissioning | C28: executing | D28: 46251 | E28: 46226.25 | F28: 46239.619 | G28: E-CAKNA PCSB | H28: E-CAKNA PCSB created for PRIVATECLOUD project record | I28: M | J28: amarja.kawade@petronas.com | K28: =IFERROR(LOOKUP(2,1/('Assignment History'!$B$5:$B$204=A28),'Assignment History'!$D$5:$D$204),IFERROR(VLOOKUP(J28,Configuration!$L$5:$M$50,2,FALSE),J28)) -> amarja.kawade@petronas.com | L28: =IF(K28=IFERROR(VLOOKUP(J28,Configuration!$L$5:$M$50,2,FALSE),J28),"Snapshot PIC","Replacement PIC") -> Snapshot PIC | M28: =IFERROR(VLOOKUP(I28,Configuration!$O$5:$P$8,2,FALSE),Configuration!$S$6) -> 2 | N28: =IFERROR(LOOKUP(2,1/('Scope Review'!$B$5:$B$204=A28),'Scope Review'!$G$5:$G$204),"Not Reviewed") -> Not Reviewed | O28: =IFERROR(LOOKUP(2,1/('Scope Review'!$B$5:$B$204=A28),'Scope Review'!$H$5:$H$204),"") | P28: =IF(AND(C28="executing",N28<>"Confirmed OOS"),M28,0) -> 2 | Q28: =IFERROR(LOOKUP(2,1/('Engineer Updates'!$B$5:$B$304=A28),'Engineer Updates'!$A$5:$A$304),"") -> 46251 | R28: =IFERROR(LOOKUP(2,1/('Engineer Updates'!$B$5:$B$304=A28),'Engineer Updates'!$E$5:$E$304),"") -> Not Started | S28: =IFERROR(LOOKUP(2,1/('Engineer Updates'!$B$5:$B$304=A28),'Engineer Updates'!$D$5:$D$304),"") -> 0 | T28: =IFERROR(LOOKUP(2,1/('Engineer Updates'!$B$5:$B$304=A28),'Engineer Updates'!$F$5:$F$304),"") -> 0 | U28: =IFERROR(LOOKUP(2,1/('Engineer Updates'!$B$5:$B$304=A28),'Engineer Updates'!$G$5:$G$304),"") -> 0 | V28: =IFERROR(LOOKUP(2,1/('Engineer Updates'!$B$5:$B$304=A28),'Engineer Updates'!$H$5:$H$304),"") -> 0 | W28: =IFERROR(LOOKUP(2,1/('Engineer Updates'!$B$5:$B$304=A28),'Engineer Updates'!$I$5:$I$304),"") -> 0 | X28: =IF(AND(C28="executing",ISERROR(SEARCH("@",K28))),"Executing without named engineer",IF(AND(N28="Confirmed OOS",C28="executing"),"Confirmed OOS still executing","")) | Y28: CSSP-Decommisioning-1708.xlsx
A29: CSSP10626318 | B29: Decommissioning | C29: executing | D29: 46251 | E29: 46226.166 | F29: 46239.29 | G29: Peer to Peer Energy Trading Platform | H29: Enhancement of Peer to Peer Energy Trading Platform for PRSB | I29: M | J29: amarja.kawade@petronas.com | K29: =IFERROR(LOOKUP(2,1/('Assignment History'!$B$5:$B$204=A29),'Assignment History'!$D$5:$D$204),IFERROR(VLOOKUP(J29,Configuration!$L$5:$M$50,2,FALSE),J29)) -> amarja.kawade@petronas.com | L29: =IF(K29=IFERROR(VLOOKUP(J29,Configuration!$L$5:$M$50,2,FALSE),J29),"Snapshot PIC","Replacement PIC") -> Snapshot PIC | M29: =IFERROR(VLOOKUP(I29,Configuration!$O$5:$P$8,2,FALSE),Configuration!$S$6) -> 2 | N29: =IFERROR(LOOKUP(2,1/('Scope Review'!$B$5:$B$204=A29),'Scope Review'!$G$5:$G$204),"Not Reviewed") -> Not Reviewed | O29: =IFERROR(LOOKUP(2,1/('Scope Review'!$B$5:$B$204=A29),'Scope Review'!$H$5:$H$204),"") | P29: =IF(AND(C29="executing",N29<>"Confirmed OOS"),M29,0) -> 2 | Q29: =IFERROR(LOOKUP(2,1/('Engineer Updates'!$B$5:$B$304=A29),'Engineer Updates'!$A$5:$A$304),"") -> 46251 | R29: =IFERROR(LOOKUP(2,1/('Engineer Updates'!$B$5:$B$304=A29),'Engineer Updates'!$E$5:$E$304),"") -> Not Started | S29: =IFERROR(LOOKUP(2,1/('Engineer Updates'!$B$5:$B$304=A29),'Engineer Updates'!$D$5:$D$304),"") -> 0 | T29: =IFERROR(LOOKUP(2,1/('Engineer Updates'!$B$5:$B$304=A29),'Engineer Updates'!$F$5:$F$304),"") -> 0 | U29: =IFERROR(LOOKUP(2,1/('Engineer Updates'!$B$5:$B$304=A29),'Engineer Updates'!$G$5:$G$304),"") -> 0 | V29: =IFERROR(LOOKUP(2,1/('Engineer Updates'!$B$5:$B$304=A29),'Engineer Updates'!$H$5:$H$304),"") -> 0 | W29: =IFERROR(LOOKUP(2,1/('Engineer Updates'!$B$5:$B$304=A29),'Engineer Updates'!$I$5:$I$304),"") -> 0 | X29: =IF(AND(C29="executing",ISERROR(SEARCH("@",K29))),"Executing without named engineer",IF(AND(N29="Confirmed OOS",C29="executing"),"Confirmed OOS still executing","")) | Y29: CSSP-Decommisioning-1708.xlsx
... A100: CSSP10984683 | B100: Provisioning | C100: executing | D100: 46251 | E100: 46225.1 | F100: 46233.104 | G100: PiriGIS | H100: Provision of Geographic Information System Infrastructure in PETRONAS Azure Cloud for Exploration | I100: M | J100: venkatesh.kalikivayi@petronas.com | K100: =IFERROR(LOOKUP(2,1/('Assignment History'!$B$5:$B$204=A100),'Assignment History'!$D$5:$D$204),IFERROR(VLOOKUP(J100,Configuration!$L$5:$M$50,2,FALSE),J100)) -> venkatesh.kalikivayi@petronas.com | L100: =IF(K100=IFERROR(VLOOKUP(J100,Configuration!$L$5:$M$50,2,FALSE),J100),"Snapshot PIC","Replacement PIC") -> Snapshot PIC | M100: =IFERROR(VLOOKUP(I100,Configuration!$O$5:$P$8,2,FALSE),Configuration!$S$6) -> 2 | N100: =IFERROR(LOOKUP(2,1/('Scope Review'!$B$5:$B$204=A100),'Scope Review'!$G$5:$G$204),"Not Reviewed") -> Not Reviewed | O100: =IFERROR(LOOKUP(2,1/('Scope Review'!$B$5:$B$204=A100),'Scope Review'!$H$5:$H$204),"") | P100: =IF(AND(C100="executing",N100<>"Confirmed OOS"),M100,0) -> 2 | Q100: =IFERROR(LOOKUP(2,1/('Engineer Updates'!$B$5:$B$304=A100),'Engineer Updates'!$A$5:$A$304),"") -> 46251 | R100: =IFERROR(LOOKUP(2,1/('Engineer Updates'!$B$5:$B$304=A100),'Engineer Updates'!$E$5:$E$304),"") -> Not Started | S100: =IFERROR(LOOKUP(2,1/('Engineer Updates'!$B$5:$B$304=A100),'Engineer Updates'!$D$5:$D$304),"") -> 0 | T100: =IFERROR(LOOKUP(2,1/('Engineer Updates'!$B$5:$B$304=A100),'Engineer Updates'!$F$5:$F$304),"") -> 0 | U100: =IFERROR(LOOKUP(2,1/('Engineer Updates'!$B$5:$B$304=A100),'Engineer Updates'!$G$5:$G$304),"") -> 0 | V100: =IFERROR(LOOKUP(2,1/('Engineer Updates'!$B$5:$B$304=A100),'Engineer Updates'!$H$5:$H$304),"") -> 0 | W100: =IFERROR(LOOKUP(2,1/('Engineer Updates'!$B$5:$B$304=A100),'Engineer Updates'!$I$5:$I$304),"") -> 0 | X100: =IF(AND(C100="executing",ISERROR(SEARCH("@",K100))),"Executing without named engineer",IF(AND(N100="Confirmed OOS",C100="executing"),"Confirmed OOS still executing","")) | Y100: CSSP-Provisioning-1708.xlsx

Sheet Daily Targets
A1: Daily Targets
A2: Manager publishes daily executing-task targets; engineers record the actual result and evidence.
A4: Target Date | B4: Request Number | C4: Snapshot Status | D4: Snapshot PIC | E4: Planned PIC | F4: Dispositioned Today | G4: Previous PIC | H4: Target Outcome | I4: Set By | J4: Set At | K4: Engineer Result | L4: Result Time | M4: Completion Evidence | N4: Carryover Reason | O4: Target Achieved | P4: Notes
A5: 46252 | B5: CSSP10231806 | C5: =IF(B5="","",IFERROR(INDEX('Task Master'!$C$5:$C$100,MATCH(B5,'Task Master'!$A$5:$A$100,0)),"")) -> executing | D5: =IF(B5="","",IFERROR(INDEX('Task Master'!$J$5:$J$100,MATCH(B5,'Task Master'!$A$5:$A$100,0)),"")) -> K.saktivelu@petronas.com | E5: =IF(B5="","",IFERROR(INDEX('Task Master'!$K$5:$K$100,MATCH(B5,'Task Master'!$A$5:$A$100,0)),"")) -> abdul.khoir@petronas.com | F5: Yes | G5: k.saktivelu@petronas.com | H5: Confirm Out-of-Scope | I5: Radit | J5: 46252 | K5: In Progress | O5: =IF(OR(A5="",B5=""),"",IF(OR(K5="Achieved",K5="Out-of-Scope Confirmed"),"Yes","No")) -> No
A6: 46252 | B6: CSSP10271745 | C6: =IF(B6="","",IFERROR(INDEX('Task Master'!$C$5:$C$100,MATCH(B6,'Task Master'!$A$5:$A$100,0)),"")) -> executing | D6: =IF(B6="","",IFERROR(INDEX('Task Master'!$J$5:$J$100,MATCH(B6,'Task Master'!$A$5:$A$100,0)),"")) -> venkatesh.kalikivayi@petronas.com | E6: =IF(B6="","",IFERROR(INDEX('Task Master'!$K$5:$K$100,MATCH(B6,'Task Master'!$A$5:$A$100,0)),"")) -> abdul.khoir@petronas.com | F6: Yes | G6: venkatesh.kalikivayi@petronas.com | H6: Confirm Out-of-Scope | I6: Radit | J6: 46252 | K6: In Progress | O6: =IF(OR(A6="",B6=""),"",IF(OR(K6="Achieved",K6="Out-of-Scope Confirmed"),"Yes","No")) -> No
A7: 46252 | B7: CSSP10328360 | C7: =IF(B7="","",IFERROR(INDEX('Task Master'!$C$5:$C$100,MATCH(B7,'Task Master'!$A$5:$A$100,0)),"")) -> executing | D7: =IF(B7="","",IFERROR(INDEX('Task Master'!$J$5:$J$100,MATCH(B7,'Task Master'!$A$5:$A$100,0)),"")) -> K.saktivelu@petronas.com | E7: =IF(B7="","",IFERROR(INDEX('Task Master'!$K$5:$K$100,MATCH(B7,'Task Master'!$A$5:$A$100,0)),"")) -> mardiansyah.rayasa@petronas.com | F7: Yes | G7: k.saktivelu@petronas.com | H7: Confirm Out-of-Scope | I7: Radit | J7: 46252 | K7: In Progress | O7: =IF(OR(A7="",B7=""),"",IF(OR(K7="Achieved",K7="Out-of-Scope Confirmed"),"Yes","No")) -> No
A8: 46252 | B8: CSSP10372916 | C8: =IF(B8="","",IFERROR(INDEX('Task Master'!$C$5:$C$100,MATCH(B8,'Task Master'!$A$5:$A$100,0)),"")) -> executing | D8: =IF(B8="","",IFERROR(INDEX('Task Master'!$J$5:$J$100,MATCH(B8,'Task Master'!$A$5:$A$100,0)),"")) -> abhishek.bhowate@petronas.com | E8: =IF(B8="","",IFERROR(INDEX('Task Master'!$K$5:$K$100,MATCH(B8,'Task Master'!$A$5:$A$100,0)),"")) -> abdul.khoir@petronas.com | F8: Yes | G8: abhishek.bhowate@petronas.com | H8: Confirm Out-of-Scope | I8: Radit | J8: 46252 | K8: In Progress | O8: =IF(OR(A8="",B8=""),"",IF(OR(K8="Achieved",K8="Out-of-Scope Confirmed"),"Yes","No")) -> No
A9: 46252 | B9: CSSP10391895 | C9: =IF(B9="","",IFERROR(INDEX('Task Master'!$C$5:$C$100,MATCH(B9,'Task Master'!$A$5:$A$100,0)),"")) -> executing | D9: =IF(B9="","",IFERROR(INDEX('Task Master'!$J$5:$J$100,MATCH(B9,'Task Master'!$A$5:$A$100,0)),"")) -> nilesh.sankpal@petronas.com | E9: =IF(B9="","",IFERROR(INDEX('Task Master'!$K$5:$K$100,MATCH(B9,'Task Master'!$A$5:$A$100,0)),"")) -> abdul.khoir@petronas.com | F9: Yes | G9: nilesh.sankpal@petronas.com | H9: Confirm Out-of-Scope | I9: Radit | J9: 46252 | K9: In Progress | O9: =IF(OR(A9="",B9=""),"",IF(OR(K9="Achieved",K9="Out-of-Scope Confirmed"),"Yes","No")) -> No
A10: 46255 | B10: CSSP10516713 | C10: =IF(B10="","",IFERROR(INDEX('Task Master'!$C$5:$C$100,MATCH(B10,'Task Master'!$A$5:$A$100,0)),"")) -> executing | D10: =IF(B10="","",IFERROR(INDEX('Task Master'!$J$5:$J$100,MATCH(B10,'Task Master'!$A$5:$A$100,0)),"")) -> amarja.kawde@petronas.com | E10: =IF(B10="","",IFERROR(INDEX('Task Master'!$K$5:$K$100,MATCH(B10,'Task Master'!$A$5:$A$100,0)),"")) -> amarja.kawade@petronas.com | F10: No | G10: amarja.kawade@petronas.com | H10: Complete Task | I10: Radit | J10: 46252 | K10: In Progress | O10: =IF(OR(A10="",B10=""),"",IF(OR(K10="Achieved",K10="Out-of-Scope Confirmed"),"Yes","No")) -> No
A11: 46255 | B11: CSSP10323752 | C11: =IF(B11="","",IFERROR(INDEX('Task Master'!$C$5:$C$100,MATCH(B11,'Task Master'!$A$5:$A$100,0)),"")) -> executing | D11: =IF(B11="","",IFERROR(INDEX('Task Master'!$J$5:$J$100,MATCH(B11,'Task Master'!$A$5:$A$100,0)),"")) -> amarja.kawade@petronas.com | E11: =IF(B11="","",IFERROR(INDEX('Task Master'!$K$5:$K$100,MATCH(B11,'Task Master'!$A$5:$A$100,0)),"")) -> amarja.kawade@petronas.com | F11: No | G11: amarja.kawade@petronas.com | H11: Complete Task | I11: Radit | J11: 46252 | K11: In Progress | O11: =IF(OR(A11="",B11=""),"",IF(OR(K11="Achieved",K11="Out-of-Scope Confirmed"),"Yes","No")) -> No
